2015-12-01 13:48:51,211 root         WARNING  Protocol problem: connection reset
2015-12-01 13:48:51,212 root         ERROR    Failed to open file
Traceback (most recent call last):
  File "./logging_test_sockets.py", line 57, in <module>
    open('/path/to/does/not/exist', 'rb')
IOError: [Errno 2] No such file or directory: '/path/to/does/not/exist'
2015-12-01 13:48:51,212 root         DEBUG    debug message
2015-12-01 13:48:51,212 root         INFO     info message
2015-12-01 13:48:51,212 root         WARNING  warn message
2015-12-01 13:48:51,212 root         ERROR    error message
2015-12-01 13:48:51,212 root         CRITICAL critical message
